<?xml version="1.0" ?>
<!-- =================================================================================== -->
<!-- |    This document was autogenerated by xacro from alpha_5_example.urdf.xacro     | -->
<!-- |    EDITING THIS FILE BY HAND IS NOT RECOMMENDED                                 | -->
<!-- =================================================================================== -->
<robot name="alpha_5_example">
  <link name="base_link"/>
  <joint name="alpha_joint" type="fixed">
    <origin rpy="0 0 0" xyz="0 0 0"/>
    <parent link="base_link"/>
    <child link="alpha_base_link"/>
  </joint>
  <material name="alpha_black">
    <color rgba="0.3 0.3 0.3 1"/>
  </material>
  <link name="alpha_base_link"/>
  <link name="alpha_m3_inline_link">
    <inertial>
      <origin rpy="0 0 0" xyz="-75e-3 -6e-3 -3e-3"/>
      <mass value="0.341"/>
      <inertia ixx="83.66e-6" ixy="14.45e-6" ixz="-38.270e-6" iyy="998.81e-6" iyz="3.14e-6" izz="1003.60e-6"/>
    </inertial>
    <visual>
      <geometry>
        <mesh filename="file://$(find ros2_control_blue_reach_5)/alpha/meshes/M3-INLINE.stl"/>
      </geometry>
      <origin rpy="0 0 0" xyz="0 0 0"/>
      <material name="alpha_black"/>
    </visual>
    <collision>
      <geometry>
        <cylinder length="0.150" radius="0.020"/>
      </geometry>
      <origin rpy="0 1.57075 0" xyz="-0.075 0 0"/>
    </collision>
  </link>
  <joint name="alpha_base_link_joint" type="fixed">
    <parent link="alpha_base_link"/>
    <child link="alpha_m3_inline_link"/>
    <origin rpy="0 0 0"/>
  </joint>
  <link name="alpha_m2_1_1_link">
    <inertial>
      <origin rpy="0 0 0" xyz="5e-3 -1e-3 16e-3"/>
      <mass value="0.194"/>
      <inertia ixx="139.1e-6" ixy="-5.970e-6" ixz="-38.480e-6" iyy="158.490e-6" iyz="-6.1e-6" izz="61.960e-6"/>
    </inertial>
    <visual>
      <geometry>
        <mesh filename="file://$(find ros2_control_blue_reach_5)/alpha/meshes/M2-1-1.stl"/>
      </geometry>
      <origin rpy="0 0 0" xyz="0 0 0"/>
      <material name="alpha_black"/>
    </visual>
    <collision>
      <geometry>
        <cylinder length="0.066" radius="0.020"/>
      </geometry>
      <origin rpy="0 0 0" xyz="0 0 0.000"/>
    </collision>
  </link>
  <joint name="alpha_axis_e" type="revolute">
    <parent link="alpha_m3_inline_link"/>
    <child link="alpha_m2_1_1_link"/>
    <origin xyz="0 0 0.014"/>
    <axis xyz="0 0 1"/>
    <limit effort="9.0" lower="0.0" upper="6.3" velocity="0.5"/>
  </joint>
  <link name="alpha_m2_joint_link">
    <inertial>
      <origin rpy="0 0 0" xyz="73.563e-3 -0.091e-3 -0.734e-3"/>
      <mass value="0.429"/>
      <inertia ixx="86.770e-6" ixy="73.130e-6" ixz="-13.160e-6" iyy="868.230e-6" iyz="0.030e-6" izz="891.460e-6"/>
    </inertial>
    <visual>
      <geometry>
        <mesh filename="file://$(find ros2_control_blue_reach_5)/alpha/meshes/M2.stl"/>
      </geometry>
      <origin rpy="0 0 0" xyz="0 0 0"/>
      <material name="alpha_black"/>
    </visual>
    <collision>
      <geometry>
        <cylinder length="0.145" radius="0.020"/>
      </geometry>
      <origin rpy="0 0 0" xyz="-0.02 0 -0.0725"/>
    </collision>
    <collision>
      <geometry>
        <cylinder length="0.040" radius="0.020"/>
      </geometry>
      <origin rpy="1.5707 0 0" xyz="0 0 0"/>
    </collision>
    <collision>
      <geometry>
        <cylinder length="0.040" radius="0.020"/>
      </geometry>
      <origin rpy="1.5707 0 0" xyz="-0.040 0 -0.1453"/>
    </collision>
  </link>
  <joint name="alpha_axis_d" type="revolute">
    <parent link="alpha_m2_1_1_link"/>
    <child link="alpha_m2_joint_link"/>
    <origin xyz="-0.02 0 0.033"/>
    <axis xyz="0 1 0"/>
    <limit effort="9.0" lower="0.0" upper="3.8" velocity="0.5"/>
  </joint>
  <link name="alpha_m2_1_2_link">
    <inertial>
      <origin rpy="0 0 0" xyz="17e-3 -26e-3 2e-3"/>
      <mass value="0.115"/>
      <inertia ixx="41.800e-6" ixy="10.170e-6" ixz="4.910e-6" iyy="28.300e-6" iyz="-5.980e-6" izz="45.020e-6"/>
    </inertial>
    <visual>
      <geometry>
        <mesh filename="file://$(find ros2_control_blue_reach_5)/alpha/meshes/M2-1-3.stl"/>
      </geometry>
      <origin rpy="0 0 0" xyz="0 0 0"/>
      <material name="alpha_black"/>
    </visual>
    <collision>
      <geometry>
        <cylinder length="0.033" radius="0.020"/>
      </geometry>
      <origin rpy="0 0 0" xyz="0.02 0 0.0165"/>
    </collision>
  </link>
  <joint name="alpha_axis_c" type="revolute">
    <parent link="alpha_m2_joint_link"/>
    <child link="alpha_m2_1_2_link"/>
    <origin rpy="0 0 3.14159" xyz="-0.04 0 -0.1453"/>
    <axis xyz="0 1 0"/>
    <limit effort="9.0" lower="0.0" upper="3.5" velocity="0.5"/>
  </joint>
  <link name="alpha_m1_link">
    <inertial>
      <origin rpy="0 0 0" xyz="-0.030e-3 -3e-3 -98e-3"/>
      <mass value="0.333"/>
      <inertia ixx="507.870e-6" ixy="-1.970e-6" ixz="4.980e-6" iyy="535.870e-6" iyz="97.900e-6" izz="76.000e-6"/>
    </inertial>
    <visual>
      <geometry>
        <mesh filename="file://$(find ros2_control_blue_reach_5)/alpha/meshes/RS1-100-101-123.stl"/>
      </geometry>
      <origin rpy="0 -1.5707 0" xyz="0 0 0"/>
      <material name="alpha_black"/>
    </visual>
    <collision>
      <geometry>
        <cylinder length="0.10975" radius="0.020"/>
      </geometry>
      <origin rpy="0 0 0" xyz="0.00 0 0.054875"/>
    </collision>
  </link>
  <joint name="alpha_axis_b" type="revolute">
    <parent link="alpha_m2_1_2_link"/>
    <child link="alpha_m1_link"/>
    <origin rpy="0 0 2.09439" xyz="0.02 0 0.033"/>
    <axis xyz="0 0 -1"/>
    <limit effort="9.0" lower="0.0" upper="6.2" velocity="0.5"/>
  </joint>
  <material name="alpha_jaws_black">
    <color rgba="0.3 0.3 0.3 1"/>
  </material>
  <joint name="alpha_jaws_joint" type="fixed">
    <origin rpy="0 0 0" xyz="0 0 0.09975"/>
    <parent link="alpha_m1_link"/>
    <child link="alpha_jaws_base_link"/>
  </joint>
  <link name="alpha_jaws_base_link">


        </link>
  <link name="alpha_push_rod"/>
  <joint name="alpha_axis_a" type="prismatic">
    <origin rpy="0 0 0" xyz="0 0 0.009"/>
    <parent link="alpha_jaws_base_link"/>
    <child link="alpha_push_rod"/>
    <axis xyz="0 0 1"/>
    <limit effort="10" lower="0" upper="0.015" velocity="10"/>
  </joint>
  <material name="alpha_standard_jaws_black">
    <color rgba="0.3 0.3 0.3 1"/>
  </material>
  <joint name="alpha_standard_jaws_joint" type="fixed">
    <origin rpy="0 0 0" xyz="0 0 0"/>
    <parent link="alpha_jaws_base_link"/>
    <child link="alpha_standard_jaws_base_link"/>
  </joint>
  <link name="alpha_standard_jaws_base_link">
    <visual>
      <geometry>
        <mesh filename="file://$(find ros2_control_blue_reach_5)/alpha/meshes/end_effectors/RS1-124.stl"/>
      </geometry>
      <material name="alpha_standard_jaws_black"/>
    </visual>
  </link>
  <link name="alpha_standard_jaws_rs1_130_link">
    <visual>
      <geometry>
        <mesh filename="file://$(find ros2_control_blue_reach_5)/alpha/meshes/end_effectors/RS1-130.stl"/>
      </geometry>
      <material name="alpha_standard_jaws_black"/>
      <origin rpy="0 0 0" xyz="0 0 0"/>
    </visual>
    <collision>
      <geometry>
        <box size="0.012 0.03 0.09"/>
      </geometry>
      <origin rpy="0 0 0" xyz="0.0 -0.008 0.045"/>
    </collision>
  </link>
  <joint name="alpha_standard_jaws_rs1_130_joint" type="revolute">
    <origin rpy="0 0 0" xyz="0 0.0155 0.0069"/>
    <parent link="alpha_standard_jaws_base_link"/>
    <child link="alpha_standard_jaws_rs1_130_link"/>
    <axis xyz="-1 0 0"/>
    <limit effort="10" lower="0" upper="0.5" velocity="10"/>
    <mimic joint="alpha_axis_a" multiplier="51" offset="0"/>
  </joint>
  <link name="alpha_standard_jaws_rs1_139_link">
    <visual>
      <geometry>
        <mesh filename="file://$(find ros2_control_blue_reach_5)/alpha/meshes/end_effectors/RS1-139.stl"/>
      </geometry>
      <material name="alpha_standard_jaws_black"/>
      <origin rpy="0 0 0" xyz="0 0 0"/>
    </visual>
    <collision>
      <geometry>
        <box size="0.012 0.03 0.09"/>
      </geometry>
      <origin rpy="0 0 0" xyz="0.0 0.008 0.045"/>
    </collision>
  </link>
  <joint name="alpha_standard_jaws_rs1_139_joint" type="revolute">
    <origin rpy="0 0 0" xyz="0 -0.0155 0.0069"/>
    <parent link="alpha_standard_jaws_base_link"/>
    <child link="alpha_standard_jaws_rs1_139_link"/>
    <axis xyz="1 0 0"/>
    <limit effort="10" lower="0" upper="0.5" velocity="10"/>
    <mimic joint="alpha_standard_jaws_rs1_130_joint" multiplier="1" offset="0"/>
  </joint>
</robot>
